Workbook

Sheet 📊Master_분석
A1: 🇰🇷 한국 5대 수출산업 월별 분석 마스터
A2: 기간: 2019-01 ~ 2026-05 (89개월, 최신=2026-05) · 산업: 철강 · 석유화학 · 조선 · 의료기기 · K푸드
A4: 1. 산업별 한눈에 보기 (Latest Month: 2026-05)
A5: 산업 | B5: 최신월 수출액 (USD) | C5: YoY % | D5: YTD 2026 (USD) | E5: YTD YoY % | F5: TTM YoY % | G5: 7년 누적 (USD) | H5: 한 줄 평
A6: 🏭 철강 | B6: =SUMIF(철강_제품!A:A,"2026-05",철강_제품!C:C) -> 1331759622 | C6: =B6/SUMIF(철강_제품!A:A,"2025-05",철강_제품!C:C)-1 -> -0.1133281 | D6: =SUMIFS(철강_제품!C:C,철강_제품!A:A,">=2026-01",철강_제품!A:A,"<=2026-05") -> 6944396619 | E6: =D6/SUMIFS(철강_제품!C:C,철강_제품!A:A,">=2025-01",철강_제품!A:A,"<=2025-05")-1 -> -0.086900703 | F6: =SUMIFS(철강_제품!C:C,철강_제품!A:A,">=2025-06",철강_제품!A:A,"<=2026-05")/SUMIFS(철강_제품!C:C,철강_제품!A:A,">=2024-06",철강_제품!A:A,"<=2025-05")-1 -> -0.098643534 | G6: =SUM(철강_제품!C4:C453) -> 142102942947 | H6: 5대 품목 중 스테인리스·강관만 양전, 열연·도금·냉연강판 두 자릿수 감소. 믹스 양극화.
A7: ⚗️ 석유화학 | B7: =SUMIF(석유화학_제품!A:A,"2026-05",석유화학_제품!C:C) -> 935732882 | C7: =B7/SUMIF(석유화학_제품!A:A,"2025-05",석유화학_제품!C:C)-1 -> 0.052232425 | D7: =SUMIFS(석유화학_제품!C:C,석유화학_제품!A:A,">=2026-01",석유화학_제품!A:A,"<=2026-05") -> 4665585453 | E7: =D7/SUMIFS(석유화학_제품!C:C,석유화학_제품!A:A,">=2025-01",석유화학_제품!A:A,"<=2025-05")-1 -> -0.062724752 | F7: =SUMIFS(석유화학_제품!C:C,석유화학_제품!A:A,">=2025-06",석유화학_제품!A:A,"<=2026-05")/SUMIFS(석유화학_제품!C:C,석유화학_제품!A:A,">=2024-06",석유화학_제품!A:A,"<=2025-05")-1 -> -0.094547005 | G7: =SUM(석유화학_제품!C4:C453) -> 87727383934 | H7: PVC·방향족 강세, 올레핀 약세 — 패키징보다 구조용 수지 우위.
A8: ⛴️ 조선 | B8: =SUMIF(조선_제품!A:A,"2026-05",조선_제품!C:C) -> 2546339928 | C8: =B8/SUMIF(조선_제품!A:A,"2025-05",조선_제품!C:C)-1 -> 0.16801417 | D8: =SUMIFS(조선_제품!C:C,조선_제품!A:A,">=2026-01",조선_제품!A:A,"<=2026-05") -> 13204817485 | E8: =D8/SUMIFS(조선_제품!C:C,조선_제품!A:A,">=2025-01",조선_제품!A:A,"<=2025-05")-1 -> 0.20823217 | F8: =SUMIFS(조선_제품!C:C,조선_제품!A:A,">=2025-06",조선_제품!A:A,"<=2026-05")/SUMIFS(조선_제품!C:C,조선_제품!A:A,">=2024-06",조선_제품!A:A,"<=2025-05")-1 -> 0.26295252 | G8: =SUM(조선_제품!C4:C453) -> 167071271683 | H8: 탱커·엔진 폭발적 성장, LNG·컨테이너선 동기고감. 고랉슨 수주 사이클.
A9: 🩺 의료기기 | B9: =SUMIF(의료기기_제품!A:A,"2026-05",의료기기_제품!C:C) -> 191670114 | C9: =B9/SUMIF(의료기기_제품!A:A,"2025-05",의료기기_제품!C:C)-1 -> 0.10564838 | D9: =SUMIFS(의료기기_제품!C:C,의료기기_제품!A:A,">=2026-01",의료기기_제품!A:A,"<=2026-05") -> 995060443 | E9: =D9/SUMIFS(의료기기_제품!C:C,의료기기_제품!A:A,">=2025-01",의료기기_제품!A:A,"<=2025-05")-1 -> 0.099052647 | F9: =SUMIFS(의료기기_제품!C:C,의료기기_제품!A:A,">=2025-06",의료기기_제품!A:A,"<=2026-05")/SUMIFS(의료기기_제품!C:C,의료기기_제품!A:A,">=2024-06",의료기기_제품!A:A,"<=2025-05")-1 -> 0.1198354 | G9: =SUM(의료기기_제품!C4:C453) -> 13904358496 | H9: 전 품목 플러스, CT 두 자릿수 성장. 안정 성장형 세터.
A10: 🍜 K푸드 | B10: =SUMIF(K푸드_제품!A:A,"2026-05",K푸드_제품!C:C) -> 319783058 | C10: =B10/SUMIF(K푸드_제품!A:A,"2025-05",K푸드_제품!C:C)-1 -> 0.013150513 | D10: =SUMIFS(K푸드_제품!C:C,K푸드_제품!A:A,">=2026-01",K푸드_제품!A:A,"<=2026-05") -> 1682664706 | E10: =D10/SUMIFS(K푸드_제품!C:C,K푸드_제품!A:A,">=2025-01",K푸드_제품!A:A,"<=2025-05")-1 -> 0.14440622 | F10: =SUMIFS(K푸드_제품!C:C,K푸드_제품!A:A,">=2025-06",K푸드_제품!A:A,"<=2026-05")/SUMIFS(K푸드_제품!C:C,K푸드_제품!A:A,">=2024-06",K푸드_제품!A:A,"<=2025-05")-1 -> 0.11083135 | G10: =SUM(K푸드_제품!C4:C453) -> 20316895703 | H10: 라면·김치 견인, 주류·음료 모멘텀 둔화. K콘텐츠 효과 지속.
A12: 2. 산업별 품목 상세 (최신월 수출액 · YoY % · YTD 수출액 · YTD YoY %)
A14: 🏭 철강 (POSCO홈딩·현대제철·동국제강·세아제강)
A15: 품목 | B15: 최신월 (USD) | C15: YoY % | D15: YTD 2026 | E15: YTD YoY % | F15: ASP 추세 | G15: 비중 | H15: 코멘트
A16: 강관 | B16: =철강_제품!C92 -> 220782049 | C16: =철강_제품!G92/100 -> 0.14974218 | D16: =SUMIFS(철강_제품!C$4:C$453,철강_제품!B$4:B$453,A16,철강_제품!A$4:A$453,">=2026-01",철강_제품!A$4:A$453,"<=2026-05") -> 977988059 | E16: =D16/SUMIFS(철강_제품!C$4:C$453,철강_제품!B$4:B$453,A16,철강_제품!A$4:A$453,">=2025-01",철강_제품!A$4:A$453,"<=2025-05")-1 -> -0.088600672 | F16: =철강_제품!E92/AVERAGE(철강_제품!E80:E92)-1 -> -0.055413797 | G16: =B16/$B$6 -> 0.16578221 | H16: 패키징용 안정, 수요 양호
A17: 냉연강판 | B17: =철강_제품!C182 -> 172136847 | C17: =철강_제품!G182/100 -> -0.15607922 | D17: =SUMIFS(철강_제품!C$4:C$453,철강_제품!B$4:B$453,A17,철강_제품!A$4:A$453,">=2026-01",철강_제품!A$4:A$453,"<=2026-05") -> 859709649 | E17: =D17/SUMIFS(철강_제품!C$4:C$453,철강_제품!B$4:B$453,A17,철강_제품!A$4:A$453,">=2025-01",철강_제품!A$4:A$453,"<=2025-05")-1 -> -0.10407921 | F17: =철강_제품!E182/AVERAGE(철강_제품!E170:E182)-1 -> -0.0048695255 | G17: =B17/$B$6 -> 0.12925519 | H17: 자동차·가전 둘 다 약세
A18: 도금강판 | B18: =철강_제품!C272 -> 433988304 | C18: =철강_제품!G272/100 -> -0.1591288 | D18: =SUMIFS(철강_제품!C$4:C$453,철강_제품!B$4:B$453,A18,철강_제품!A$4:A$453,">=2026-01",철강_제품!A$4:A$453,"<=2026-05") -> 2389793014 | E18: =D18/SUMIFS(철강_제품!C$4:C$453,철강_제품!B$4:B$453,A18,철강_제품!A$4:A$453,">=2025-01",철강_제품!A$4:A$453,"<=2025-05")-1 -> -0.056007881 | F18: =철강_제품!E272/AVERAGE(철강_제품!E260:E272)-1 -> -0.033729481 | G18: =B18/$B$6 -> 0.32587585 | H18: 철강 품목 중 하락폭 최대
A19: 스테인리스 열연 | B19: =철강_제품!C362 -> 137469101 | C19: =철강_제품!G362/100 -> 0.11471851 | D19: =SUMIFS(철강_제품!C$4:C$453,철강_제품!B$4:B$453,A19,철강_제품!A$4:A$453,">=2026-01",철강_제품!A$4:A$453,"<=2026-05") -> 676547058 | E19: =D19/SUMIFS(철강_제품!C$4:C$453,철강_제품!B$4:B$453,A19,철강_제품!A$4:A$453,">=2025-01",철강_제품!A$4:A$453,"<=2025-05")-1 -> -0.041392596 | F19: =철강_제품!E362/AVERAGE(철강_제품!E350:E362)-1 -> 0.068817521 | G19: =B19/$B$6 -> 0.10322366 | H19: 고부가가치 서브세그먼트 강세
A20: 열연강판 | B20: =철강_제품!C452 -> 367383321 | C20: =철강_제품!G452/100 -> -0.21252988 | D20: =SUMIFS(철강_제품!C$4:C$453,철강_제품!B$4:B$453,A20,철강_제품!A$4:A$453,">=2026-01",철강_제품!A$4:A$453,"<=2026-05") -> 2040358839 | E20: =D20/SUMIFS(철강_제품!C$4:C$453,철강_제품!B$4:B$453,A20,철강_제품!A$4:A$453,">=2025-01",철강_제품!A$4:A$453,"<=2025-05")-1 -> -0.12630313 | F20: =철강_제품!E452/AVERAGE(철강_제품!E440:E452)-1 -> 0.070401018 | G20: =B20/$B$6 -> 0.27586309 | H20: 구조 부진 + 공급 과잉으로 약세
A22: ⚗️ 석유화학 (LG화학·롤론·금호·한화솔루션)
A23: 품목 | B23: 최신월 (USD) | C23: YoY % | D23: YTD 2026 | E23: YTD YoY % | F23: ASP 추세 | G23: 비중 | H23: 코멘트
A24: PE | B24: =석유화학_제품!C92 -> 213481993 | C24: =석유화학_제품!G92/100 -> 0.074709927 | D24: =SUMIFS(석유화학_제품!C$4:C$453,석유화학_제품!B$4:B$453,A24,석유화학_제품!A$4:A$453,">=2026-01",석유화학_제품!A$4:A$453,"<=2026-05") -> 1015085598 | E24: =D24/SUMIFS(석유화학_제품!C$4:C$453,석유화학_제품!B$4:B$453,A24,석유화학_제품!A$4:A$453,">=2025-01",석유화학_제품!A$4:A$453,"<=2025-05")-1 -> -0.012229748 | F24: =석유화학_제품!E92/AVERAGE(석유화학_제품!E80:E92)-1 -> 0.4671259 | G24: =B24/$B$7 -> 0.22814416 | H24: 범용 수지 견조, 중국 접적 안정
A25: PP | B25: =석유화학_제품!C182 -> 149270655 | C25: =석유화학_제품!G182/100 -> -0.012784866 | D25: =SUMIFS(석유화학_제품!C$4:C$453,석유화학_제품!B$4:B$453,A25,석유화학_제품!A$4:A$453,">=2026-01",석유화학_제품!A$4:A$453,"<=2026-05") -> 767213936 | E25: =D25/SUMIFS(석유화학_제품!C$4:C$453,석유화학_제품!B$4:B$453,A25,석유화학_제품!A$4:A$453,">=2025-01",석유화학_제품!A$4:A$453,"<=2025-05")-1 -> -0.059017793 | F25: =석유화학_제품!E182/AVERAGE(석유화학_제품!E170:E182)-1 -> 0.48249163 | G25: =B25/$B$7 -> 0.15952272 | H25: 자동차·포장재, 의료·위생재로 수요 유지
A26: PVC·기타수지 | B26: =석유화학_제품!C272 -> 206783403 | C26: =석유화학_제품!G272/100 -> 0.26619773 | D26: =SUMIFS(석유화학_제품!C$4:C$453,석유화학_제품!B$4:B$453,A26,석유화학_제품!A$4:A$453,">=2026-01",석유화학_제품!A$4:A$453,"<=2026-05") -> 981592072 | E26: =D26/SUMIFS(석유화학_제품!C$4:C$453,석유화학_제품!B$4:B$453,A26,석유화학_제품!A$4:A$453,">=2025-01",석유화학_제품!A$4:A$453,"<=2025-05")-1 -> 0.096393192 | F26: =석유화학_제품!E272/AVERAGE(석유화학_제품!E260:E272)-1 -> 0.27584438 | G26: =B26/$B$7 -> 0.2209855 | H26: 건설·배관 수요 회복, +26.6% 급반등
A27: 방향족(벤젠·자일렌) | B27: =석유화학_제품!C362 -> 180800691 | C27: =석유화학_제품!G362/100 -> 0.32919748 | D27: =SUMIFS(석유화학_제품!C$4:C$453,석유화학_제품!B$4:B$453,"방향족(벤젠·자일렌)",석유화학_제품!A$4:A$453,">=2026-01",석유화학_제품!A$4:A$453,"<=2026-05") -> 904805700 | E27: =D27/SUMIFS(석유화학_제품!C$4:C$453,석유화학_제품!B$4:B$453,"방향족(벤젠·자일렌)",석유화학_제품!A$4:A$453,">=2025-01",석유화학_제품!A$4:A$453,"<=2025-05")-1 -> -0.1621116 | F27: =석유화학_제품!E362/AVERAGE(석유화학_제품!E350:E362)-1 -> 0.35073977 | G27: =B27/$B$7 -> 0.19321827 | H27: PX·벤젠 스프레드 개선, 월간 최고 성장
A28: 올레핀(에틸렌·프로필렌) | B28: =석유화학_제품!C452 -> 185396140 | C28: =석유화학_제품!G452/100 -> -0.22785459 | D28: =SUMIFS(석유화학_제품!C$4:C$453,석유화학_제품!B$4:B$453,"올레핀(에틸렌·프로필렌)",석유화학_제품!A$4:A$453,">=2026-01",석유화학_제품!A$4:A$453,"<=2026-05") -> 996888147 | E28: =D28/SUMIFS(석유화학_제품!C$4:C$453,석유화학_제품!B$4:B$453,"올레핀(에틸렌·프로필렌)",석유화학_제품!A$4:A$453,">=2025-01",석유화학_제품!A$4:A$453,"<=2025-05")-1 -> -0.1403728 | F28: =석유화학_제품!E452/AVERAGE(석유화학_제품!E440:E452)-1 -> 0.47035203 | G28: =B28/$B$7 -> 0.19812934 | H28: 나프단서·에틸렌 공급과잉, 지속 약세
A30: ⛴️ 조선 (HD한국조선해양·삼성중공업·한화오션·HD현대중공업)
A31: 품목 | B31: 최신월 (USD) | C31: YoY % | D31: YTD 2026 | E31: YTD YoY % | F31: ASP 추세 | G31: 비중 | H31: 코멘트
A32: 기타선박(LNG·컨테이너) | B32: =조선_제품!C92 -> 615633660 | C32: =조선_제품!G92/100 -> -0.57494495 | D32: =SUMIFS(조선_제품!C$4:C$453,조선_제품!B$4:B$453,A32,조선_제품!A$4:A$453,">=2026-01",조선_제품!A$4:A$453,"<=2026-05") -> 2458646760 | E32: =D32/SUMIFS(조선_제품!C$4:C$453,조선_제품!B$4:B$453,A32,조선_제품!A$4:A$453,">=2025-01",조선_제품!A$4:A$453,"<=2025-05")-1 -> -0.57222126 | F32: =조선_제품!E92/AVERAGE(조선_제품!E80:E92)-1 -> 1.5242651 | G32: =B32/$B$8 -> 0.24177199 | H32: 월별 등락폭 차이 큼 — 인도시 매출인식
A33: 선박엔진 | B33: =조선_제품!C182 -> 91777891 | C33: =조선_제품!G182/100 -> 0.56053686 | D33: =SUMIFS(조선_제품!C$4:C$453,조선_제품!B$4:B$453,A33,조선_제품!A$4:A$453,">=2026-01",조선_제품!A$4:A$453,"<=2026-05") -> 460315376 | E33: =D33/SUMIFS(조선_제품!C$4:C$453,조선_제품!B$4:B$453,A33,조선_제품!A$4:A$453,">=2025-01",조선_제품!A$4:A$453,"<=2025-05")-1 -> -0.00038869965 | F33: =조선_제품!E182/AVERAGE(조선_제품!E170:E182)-1 -> 0.033609712 | G33: =B33/$B$8 -> 0.036043063 | H33: 애프터마켓·AS 매출 견조, 고수익성
A34: 어선·작업선 | B34: =조선_제품!C272 -> 0 | C34: =조선_제품!G272/100 -> -1 | D34: =SUMIFS(조선_제품!C$4:C$453,조선_제품!B$4:B$453,A34,조선_제품!A$4:A$453,">=2026-01",조선_제품!A$4:A$453,"<=2026-05") -> 5806607 | E34: =D34/SUMIFS(조선_제품!C$4:C$453,조선_제품!B$4:B$453,A34,조선_제품!A$4:A$453,">=2025-01",조선_제품!A$4:A$453,"<=2025-05")-1 -> 0.071660298 | F34: =조선_제품!E272/AVERAGE(조선_제품!E260:E272)-1 -> -1 | G34: =B34/$B$8 -> 0 | H34: 니치마켓, 변동 극심
A35: 탱커 | B35: =조선_제품!C362 -> 1838928377 | C35: =조선_제품!G362/100 -> 1.7338464 | D35: =SUMIFS(조선_제품!C$4:C$453,조선_제품!B$4:B$453,A35,조선_제품!A$4:A$453,">=2026-01",조선_제품!A$4:A$453,"<=2026-05") -> 9520763857 | E35: =D35/SUMIFS(조선_제품!C$4:C$453,조선_제품!B$4:B$453,A35,조선_제품!A$4:A$453,">=2025-01",조선_제품!A$4:A$453,"<=2025-05")-1 -> 1.2812936 | F35: =조선_제품!E362/AVERAGE(조선_제품!E350:E362)-1 -> 0.17566511 | G35: =B35/$B$8 -> 0.72218495 | H35: +173% 폭등, 부육해운업 수설
A36: 해양구조물 | B36: =조선_제품!C452 -> 0 | C36: =조선_제품!G452/100 -> -1 | D36: =SUMIFS(조선_제품!C$4:C$453,조선_제품!B$4:B$453,A36,조선_제품!A$4:A$453,">=2026-01",조선_제품!A$4:A$453,"<=2026-05") -> 759284885 | E36: =D36/SUMIFS(조선_제품!C$4:C$453,조선_제품!B$4:B$453,A36,조선_제품!A$4:A$453,">=2025-01",조선_제품!A$4:A$453,"<=2025-05")-1 -> 0.4002532 | F36: =조선_제품!E452/AVERAGE(조선_제품!E440:E452)-1 -> -1 | G36: =B36/$B$8 -> 0 | H36: FPSO·모듈 대형 프로젝트
A38: 🩺 의료기기 (삼성메디슨·제이아이테크·루나소스 등)
A39: 품목 | B39: 최신월 (USD) | C39: YoY % | D39: YTD 2026 | E39: YTD YoY % | F39: ASP 추세 | G39: 비중 | H39: 코멘트
A40: CT | B40: =의료기기_제품!C92 -> 3463360 | C40: =의료기기_제품!G92/100 -> 0.20373798 | D40: =SUMIFS(의료기기_제품!C$4:C$453,의료기기_제품!B$4:B$453,A40,의료기기_제품!A$4:A$453,">=2026-01",의료기기_제품!A$4:A$453,"<=2026-05") -> 11834989 | E40: =IFERROR(D40/SUMIFS(의료기기_제품!C$4:C$453,의료기기_제품!B$4:B$453,A40,의료기기_제품!A$4:A$453,">=2025-01",의료기기_제품!A$4:A$453,"<=2025-05")-1,"-") -> -0.036162233 | F40: =IFERROR(의료기기_제품!E92/AVERAGE(의료기기_제품!E80:E92)-1,"-") -> 0.065037942 | G40: =B40/$B$9 -> 0.018069379 | H40: +20% 이상 고성장, 장비 고가제품
A41: 기타 의료기기 | B41: =의료기기_제품!C182 -> 95432540 | C41: =의료기기_제품!G182/100 -> 0.14006 | D41: =SUMIFS(의료기기_제품!C$4:C$453,의료기기_제품!B$4:B$453,A41,의료기기_제품!A$4:A$453,">=2026-01",의료기기_제품!A$4:A$453,"<=2026-05") -> 486812332 | E41: =IFERROR(D41/SUMIFS(의료기기_제품!C$4:C$453,의료기기_제품!B$4:B$453,A41,의료기기_제품!A$4:A$453,">=2025-01",의료기기_제품!A$4:A$453,"<=2025-05")-1,"-") -> 0.15217724 | F41: =IFERROR(의료기기_제품!E182/AVERAGE(의료기기_제품!E170:E182)-1,"-") -> 0.24792172 | G41: =B41/$B$9 -> 0.49789995 | H41: 최대 품목, 안정 성장
A42: 정형외과용(임플란트) | B42: =IFERROR(의료기기_제품!C272,"-") -> 0 | C42: =IFERROR(의료기기_제품!G272/100,"-") -> 0 | D42: 데이터 없음 | E42: - | F42: - | G42: - | H42: 원본 데이터 공란 — 확인 필요
A43: 초음파·진단 | B43: =의료기기_제품!C362 -> 74803480 | C43: =의료기기_제품!G362/100 -> 0.084090683 | D43: =SUMIFS(의료기기_제품!C$4:C$453,의료기기_제품!B$4:B$453,A43,의료기기_제품!A$4:A$453,">=2026-01",의료기기_제품!A$4:A$453,"<=2026-05") -> 399209831 | E43: =D43/SUMIFS(의료기기_제품!C$4:C$453,의료기기_제품!B$4:B$453,A43,의료기기_제품!A$4:A$453,">=2025-01",의료기기_제품!A$4:A$453,"<=2025-05")-1 -> 0.083644362 | F43: =의료기기_제품!E362/AVERAGE(의료기기_제품!E350:E362)-1 -> 0.084096286 | G43: =B43/$B$9 -> 0.39027201 | H43: POC 진단 확대, 안정적 성장
A44: 치과용 | B44: =의료기기_제품!C452 -> 17970734 | C44: =의료기기_제품!G452/100 -> 0.011367429 | D44: =SUMIFS(의료기기_제품!C$4:C$453,의료기기_제품!B$4:B$453,A44,의료기기_제품!A$4:A$453,">=2026-01",의료기기_제품!A$4:A$453,"<=2026-05") -> 97203291 | E44: =D44/SUMIFS(의료기기_제품!C$4:C$453,의료기기_제품!B$4:B$453,A44,의료기기_제품!A$4:A$453,">=2025-01",의료기기_제품!A$4:A$453,"<=2025-05")-1 -> -0.048801747 | F44: =의료기기_제품!E452/AVERAGE(의료기기_제품!E440:E452)-1 -> -0.22557503 | G44: =B44/$B$9 -> 0.093758665 | H44: 임플란트·교정재 수출 확대
A46: 🍜 K푸드 (CJ제일제당·농심·오뛸기·하이트진로 등)
A47: 품목 | B47: 최신월 (USD) | C47: YoY % | D47: YTD 2026 | E47: YTD YoY % | F47: ASP 추세 | G47: 비중 | H47: 코멘트
...

Sheet 철강_제품
A1: 철강 · 제품믹스 월별 (POSCO홀딩스, 현대제철, 동국제강, 세아제강)
A3: 월 | B3: 품목 | C3: 수출액(USD) | D3: 중량(kg) | E3: ASP(USD/kg) | F3: MoM(%) | G3: YoY(%)
A4: 2019-01 | B4: 강관 | C4: 194999538 | D4: 150907632 | E4: 1.2921781
A5: 2019-02 | B5: 강관 | C5: 214621248 | D5: 176210078 | E5: 1.2179851 | F5: 10.062439
A6: 2019-03 | B6: 강관 | C6: 199704225 | D6: 157139615 | E6: 1.2708713 | F6: -6.9503943
A7: 2019-04 | B7: 강관 | C7: 180770898 | D7: 136195815 | E7: 1.3272867 | F7: -9.4806842
A8: 2019-05 | B8: 강관 | C8: 181149873 | D8: 141540986 | E8: 1.2798404 | F8: 0.20964381
A9: 2019-06 | B9: 강관 | C9: 192854158 | D9: 149651054 | E9: 1.2886923 | F9: 6.4611058
A10: 2019-07 | B10: 강관 | C10: 196925556 | D10: 154386112 | E10: 1.2755393 | F10: 2.1111279
A11: 2019-08 | B11: 강관 | C11: 158142497 | D11: 128251579 | E11: 1.2330647 | F11: -19.694274
A12: 2019-09 | B12: 강관 | C12: 154821435 | D12: 135214826 | E12: 1.1450034 | F12: -2.100044
A13: 2019-10 | B13: 강관 | C13: 153472710 | D13: 126111764 | E13: 1.2169579 | F13: -0.87114875
A14: 2019-11 | B14: 강관 | C14: 152861473 | D14: 120250717 | E14: 1.2711897 | F14: -0.39827081
A15: 2019-12 | B15: 강관 | C15: 190280502 | D15: 154843921 | E15: 1.2288535 | F15: 24.479045
A16: 2020-01 | B16: 강관 | C16: 145907769 | D16: 119117223 | E16: 1.2249091 | F16: -23.319643 | G16: -25.175326
A17: 2020-02 | B17: 강관 | C17: 165897800 | D17: 149380192 | E17: 1.1105743 | F17: 13.700457 | G17: -22.702062
A18: 2020-03 | B18: 강관 | C18: 180659103 | D18: 162275372 | E18: 1.1132873 | F18: 8.8978293 | G18: -9.5366645
A19: 2020-04 | B19: 강관 | C19: 164784072 | D19: 143223015 | E19: 1.1505418 | F19: -8.7872854 | G19: -8.8436945
A20: 2020-05 | B20: 강관 | C20: 135533009 | D20: 116102398 | E20: 1.1673575 | F20: -17.751147 | G20: -25.181836
A21: 2020-06 | B21: 강관 | C21: 132136250 | D21: 112606784 | E21: 1.1734306 | F21: -2.5062227 | G21: -31.483847
A22: 2020-07 | B22: 강관 | C22: 144619283 | D22: 115456917 | E22: 1.2525822 | F22: 9.4470919 | G22: -26.561445
A23: 2020-08 | B23: 강관 | C23: 113801620 | D23: 95466439 | E23: 1.1920589 | F23: -21.309512 | G23: -28.038559
A24: 2020-09 | B24: 강관 | C24: 139682385 | D24: 111226710 | E24: 1.2558349 | F24: 22.742001 | G24: -9.7783941
A25: 2020-10 | B25: 강관 | C25: 153521640 | D25: 147982885 | E25: 1.0374283 | F25: 9.9076594 | G25: 0.03188189
A26: 2020-11 | B26: 강관 | C26: 134724153 | D26: 121223733 | E26: 1.1113678 | F26: -12.244194 | G26: -11.8652
A27: 2020-12 | B27: 강관 | C27: 148985851 | D27: 142464292 | E27: 1.0457768 | F27: 10.585851 | G27: -21.701988
... A92: 2026-05 | B92: 강관 | C92: 220782049 | D92: 185832045 | E92: 1.1880731 | F92: 1.1212895 | G92: 14.974218
A93: 2026-06 | B93: 강관 | F93: 0 | G93: 7.0105225
A94: 2019-01 | B94: 냉연강판 | C94: 215899479 | D94: 339023225 | E94: 0.63682799
A95: 2019-02 | B95: 냉연강판 | C95: 199608114 | D95: 321727257 | E95: 0.62042649 | F95: -7.5458102
A96: 2019-03 | B96: 냉연강판 | C96: 200364813 | D96: 326350996 | E96: 0.61395496 | F96: 0.3790923
A97: 2019-04 | B97: 냉연강판 | C97: 176146410 | D97: 284952030 | E97: 0.61816163 | F97: -12.087154
A98: 2019-05 | B98: 냉연강판 | C98: 194642755 | D98: 318390007 | E98: 0.61133437 | F98: 10.500552
A99: 2019-06 | B99: 냉연강판 | C99: 183992362 | D99: 299248864 | E99: 0.61484732 | F99: -5.4717644
A100: 2019-07 | B100: 냉연강판 | C100: 203773566 | D100: 330408584 | E100: 0.61673206 | F100: 10.751101
A101: 2019-08 | B101: 냉연강판 | C101: 210415571 | D101: 345134682 | E101: 0.6096622 | F101: 3.2595028
A102: 2019-09 | B102: 냉연강판 | C102: 173545950 | D102: 284581800 | E102: 0.609828 | F102: -17.522287
A103: 2019-10 | B103: 냉연강판 | C103: 173688447 | D103: 288337309 | E103: 0.60237937 | F103: 0.08210909
A104: 2019-11 | B104: 냉연강판 | C104: 194182119 | D104: 328159213 | E104: 0.59173143 | F104: 11.799099
A105: 2019-12 | B105: 냉연강판 | C105: 212196314 | D105: 379451395 | E105: 0.5592187 | F105: 9.2769587
...

Sheet 철강_국가
A1: 철강 · 향지별 월별 (대표 HS 7208, 7210)
A3: 월 | B3: 향지 | C3: 수출액(USD) | D3: 비중(%) | E3: ASP(USD/kg) | F3: MoM(%) | G3: YoY(%)
A4: 2019-01 | B4: 아랍에미리트 연합 | C4: 7650877 | D4: 0.72032122 | E4: 0.76156235
A5: 2019-02 | B5: 아랍에미리트 연합 | C5: 7117356 | D5: 0.75048759 | E5: 0.72075469 | F5: -6.9733313
A6: 2019-03 | B6: 아랍에미리트 연합 | C6: 4318931 | D6: 0.46391278 | E6: 0.72457067 | F6: -39.318323
A7: 2019-04 | B7: 아랍에미리트 연합 | C7: 3741216 | D7: 0.38941206 | E7: 0.71078876 | F7: -13.376342
A8: 2019-05 | B8: 아랍에미리트 연합 | C8: 7287369 | D8: 0.73826937 | E8: 0.71975842 | F8: 94.786107
A9: 2019-06 | B9: 아랍에미리트 연합 | C9: 9124364 | D9: 0.99425349 | E9: 0.77775425 | F9: 25.207932
A10: 2019-07 | B10: 아랍에미리트 연합 | C10: 11688948 | D10: 1.2394486 | E10: 0.78690854 | F10: 28.106989
A11: 2019-08 | B11: 아랍에미리트 연합 | C11: 13310332 | D11: 1.4069107 | E11: 0.7323451 | F11: 13.871086
A12: 2019-09 | B12: 아랍에미리트 연합 | C12: 4704283 | D12: 0.54739869 | E12: 0.62514583 | F12: -64.656907
A13: 2019-10 | B13: 아랍에미리트 연합 | C13: 7124362 | D13: 0.83506538 | E13: 0.63621622 | F13: 51.444163
A14: 2019-11 | B14: 아랍에미리트 연합 | C14: 8725264 | D14: 0.98787498 | E14: 0.62406641 | F14: 22.470812
A15: 2019-12 | B15: 아랍에미리트 연합 | C15: 14547176 | D15: 1.4948538 | E15: 0.54462742 | F15: 66.724766
A16: 2020-01 | B16: 아랍에미리트 연합 | C16: 5852659 | D16: 0.66474605 | E16: 0.73311514 | F16: -59.767731 | G16: -23.503423
A17: 2020-02 | B17: 아랍에미리트 연합 | C17: 4379062 | D17: 0.52720525 | E17: 0.63421632 | F17: -25.178248 | G17: -38.473472
A18: 2020-03 | B18: 아랍에미리트 연합 | C18: 17158099 | D18: 1.9346035 | E18: 0.5732367 | F18: 291.82133 | G18: 297.27653
A19: 2020-04 | B19: 아랍에미리트 연합 | C19: 7846947 | D19: 1.1557906 | E19: 0.79579363 | F19: -54.266804 | G19: 109.74322
A20: 2020-05 | B20: 아랍에미리트 연합 | C20: 7538074 | D20: 1.2318755 | E20: 0.5758269 | F20: -3.9362188 | G20: 3.4402677
A21: 2020-06 | B21: 아랍에미리트 연합 | C21: 8064046 | D21: 1.0274762 | E21: 0.47459649 | F21: 6.9775383 | G21: -11.620733
A22: 2020-07 | B22: 아랍에미리트 연합 | C22: 5421335 | D22: 0.66825002 | E22: 0.66060864 | F22: -32.771527 | G22: -53.619992
A23: 2020-08 | B23: 아랍에미리트 연합 | C23: 4896369 | D23: 0.62581245 | E23: 0.67940506 | F23: -9.6833345 | G23: -63.213773
A24: 2020-09 | B24: 아랍에미리트 연합 | C24: 1460654 | D24: 0.16779048 | E24: 0.68114906 | F24: -70.168629 | G24: -68.95055
A25: 2020-10 | B25: 아랍에미리트 연합 | C25: 23295600 | D25: 2.8934361 | E25: 0.49818178 | F25: 1494.8746 | G25: 226.98507
A26: 2020-11 | B26: 아랍에미리트 연합 | C26: 10255876 | D26: 1.245716 | E26: 0.64838657 | F26: -55.975051 | G26: 17.5423
A27: 2020-12 | B27: 아랍에미리트 연합 | C27: 13605586 | D27: 1.5177315 | E27: 0.6749513 | F27: 32.661374 | G27: -6.4726652
... A92: 2026-05 | B92: 아랍에미리트 연합 | C92: 1235887 | D92: 0.15422146 | E92: 1.0620643 | F92: 124.76026 | G92: -86.696343
A93: 2021-11 | B93: 안티가 바부다 | C93: 127145 | D93: 0.0097541111 | E93: 1.6410041
A94: 2022-01 | B94: 안티가 바부다 | C94: 32656 | D94: 0.0022388643 | E94: 1.641005 | F94: -74.315938
A95: 2022-02 | B95: 안티가 바부다 | C95: 32176 | D95: 0.0026524488 | E95: 1.603988 | F95: -1.4698677
A96: 2022-11 | B96: 안티가 바부다 | C96: 37896 | D96: 0.0042060162 | E96: 1.0550111 | F96: 17.777225
A97: 2023-04 | B97: 안티가 바부다 | C97: 35031 | D97: 0.002931027 | E97: 1.0964319 | F97: -7.5601647
A98: 2023-07 | B98: 안티가 바부다 | C98: 19574 | D98: 0.0016828768 | E98: 1.0340201 | F98: -44.123776
A99: 2023-10 | B99: 안티가 바부다 | C99: 64158 | D99: 0.0061604422 | E99: 0.9984127 | F99: 227.77153
A100: 2024-06 | B100: 안티가 바부다 | C100: 37753 | D100: 0.00381387 | E100: 0.91500242 | F100: -41.156208
A101: 2024-08 | B101: 안티가 바부다 | C101: 39654 | D101: 0.003632717 | E101: 0.80499391 | F101: 5.0353614
A102: 2024-10 | B102: 안티가 바부다 | C102: 18109 | D102: 0.0017056062 | E102: 1.0099833 | F102: -54.332476
A103: 2026-03 | B103: 안티가 바부다 | C103: 14738 | D103: 0.0016321068 | E103: 0.96896778 | F103: -18.615053
A104: 2021-06 | B104: 아르메니아 | C104: 698252 | D104: 0.064797974 | E104: 1.5554041
A105: 2024-03 | B105: 아르메니아 | C105: 121044 | D105: 0.010492339 | E105: 1.2248937 | F105: -82.664711
...

Sheet 석유화학_제품
A1: 석유화학 · 제품믹스 월별 (LG화학, 롯데케미칼, 대한유화, 금호석유)
A3: 월 | B3: 품목 | C3: 수출액(USD) | D3: 중량(kg) | E3: ASP(USD/kg) | F3: MoM(%) | G3: YoY(%)
A4: 2019-01 | B4: PE | C4: 219076752 | D4: 182485211 | E4: 1.2005178
A5: 2019-02 | B5: PE | C5: 185428497 | D5: 157176245 | E5: 1.1797489 | F5: -15.359117
A6: 2019-03 | B6: PE | C6: 204235805 | D6: 170627170 | E6: 1.1969712 | F6: 10.14262
A7: 2019-04 | B7: PE | C7: 203217466 | D7: 168385459 | E7: 1.2068588 | F7: -0.49860944
A8: 2019-05 | B8: PE | C8: 198674931 | D8: 164267026 | E8: 1.2094632 | F8: -2.2353074
A9: 2019-06 | B9: PE | C9: 179128393 | D9: 152087229 | E9: 1.1778004 | F9: -9.8384521
A10: 2019-07 | B10: PE | C10: 214903613 | D10: 191025331 | E10: 1.1250006 | F10: 19.971831
A11: 2019-08 | B11: PE | C11: 206255342 | D11: 183483560 | E11: 1.124108 | F11: -4.0242557
A12: 2019-09 | B12: PE | C12: 181213380 | D12: 170761124 | E12: 1.0612098 | F12: -12.141243
A13: 2019-10 | B13: PE | C13: 189225424 | D13: 180300656 | E13: 1.0494994 | F13: 4.4213314
A14: 2019-11 | B14: PE | C14: 185961706 | D14: 180965355 | E14: 1.0276094 | F14: -1.7247777
A15: 2019-12 | B15: PE | C15: 187529306 | D15: 188079646 | E15: 0.9970739 | F15: 0.84296925
A16: 2020-01 | B16: PE | C16: 177574272 | D16: 177123029 | E16: 1.0025476 | F16: -5.3085218 | G16: -18.944265
A17: 2020-02 | B17: PE | C17: 165890795 | D17: 162015794 | E17: 1.0239174 | F17: -6.5794875 | G17: -10.536515
A18: 2020-03 | B18: PE | C18: 186781060 | D18: 187497371 | E18: 0.99617962 | F18: 12.592781 | G18: -8.5463687
A19: 2020-04 | B19: PE | C19: 182623693 | D19: 210734827 | E19: 0.86660423 | F19: -2.2257969 | G19: -10.13386
A20: 2020-05 | B20: PE | C20: 172882489 | D20: 207036655 | E20: 0.83503324 | F20: -5.3340308 | G20: -12.982233
A21: 2020-06 | B21: PE | C21: 174740415 | D21: 196172301 | E21: 0.89074968 | F21: 1.0746756 | G21: -2.4496273
A22: 2020-07 | B22: PE | C22: 200324439 | D22: 209992361 | E22: 0.9539606 | F22: 14.64116 | G22: -6.7840525
A23: 2020-08 | B23: PE | C23: 187491764 | D23: 184750886 | E23: 1.0148355 | F23: -6.4059458 | G23: -9.0972567
A24: 2020-09 | B24: PE | C24: 206063821 | D24: 201740682 | E24: 1.0214292 | F24: 9.9055322 | G24: 13.713359
A25: 2020-10 | B25: PE | C25: 189985472 | D25: 180306095 | E25: 1.053683 | F25: -7.8026065 | G25: 0.40166273
A26: 2020-11 | B26: PE | C26: 162206720 | D26: 154185811 | E26: 1.0520211 | F26: -14.621514 | G26: -12.774128
A27: 2020-12 | B27: PE | C27: 168342508 | D27: 155858802 | E27: 1.0800963 | F27: 3.7826965 | G27: -10.23136
... A92: 2026-05 | B92: PE | C92: 213481993 | D92: 123915064 | E92: 1.722809 | F92: -5.7072645 | G92: 7.4709927
A93: 2026-06 | B93: PE | F93: 0 | G93: 7.5897429
A94: 2019-01 | B94: PP | C94: 172883594 | D94: 137803424 | E94: 1.2545668
A95: 2019-02 | B95: PP | C95: 175707888 | D95: 140183237 | E95: 1.2534158 | F95: 1.6336391
A96: 2019-03 | B96: PP | C96: 182318835 | D96: 143472625 | E96: 1.2707569 | F96: 3.7624646
A97: 2019-04 | B97: PP | C97: 167764127 | D97: 128141532 | E97: 1.3092096 | F97: -7.9831072
A98: 2019-05 | B98: PP | C98: 180202934 | D98: 137809529 | E98: 1.3076232 | F98: 7.4144617
A99: 2019-06 | B99: PP | C99: 148139780 | D99: 113665760 | E99: 1.3032929 | F99: -17.792804
A100: 2019-07 | B100: PP | C100: 204199613 | D100: 164386268 | E100: 1.2421939 | F100: 37.842525
A101: 2019-08 | B101: PP | C101: 193713437 | D101: 159914742 | E101: 1.2113545 | F101: -5.1352575
A102: 2019-09 | B102: PP | C102: 188844146 | D102: 161660318 | E102: 1.168154 | F102: -2.5136568
A103: 2019-10 | B103: PP | C103: 192147304 | D103: 166232808 | E103: 1.1558928 | F103: 1.749145
A104: 2019-11 | B104: PP | C104: 161192226 | D104: 139440807 | E104: 1.1559903 | F104: -16.110077
A105: 2019-12 | B105: PP | C105: 181221084 | D105: 163286619 | E105: 1.1098343 | F105: 12.425449
...

Sheet 석유화학_국가
A1: 석유화학 · 향지별 월별 (대표 HS 390110, 390210)
A3: 월 | B3: 향지 | C3: 수출액(USD) | D3: 비중(%) | E3: ASP(USD/kg) | F3: MoM(%) | G3: YoY(%)
A4: 2019-01 | B4: 아랍에미리트 연합 | C4: 268782 | D4: 0.10367714 | E4: 1.2559907
A5: 2019-02 | B5: 아랍에미리트 연합 | C5: 335429 | D5: 0.13238199 | E5: 1.2298038 | F5: 24.795931
A6: 2019-03 | B6: 아랍에미리트 연합 | C6: 184958 | D6: 0.069227387 | E6: 1.3234919 | F6: -44.85927
A7: 2019-04 | B7: 아랍에미리트 연합 | C7: 872337 | D7: 0.35155511 | E7: 1.4092682 | F7: 371.64059
A8: 2019-05 | B8: 아랍에미리트 연합 | C8: 320596 | D8: 0.12319715 | E8: 1.3866609 | F8: -63.248607
A9: 2019-06 | B9: 아랍에미리트 연합 | C9: 603632 | D9: 0.27553538 | E9: 1.4236604 | F9: 88.28432
A10: 2019-07 | B10: 아랍에미리트 연합 | C10: 801121 | D10: 0.27329116 | E10: 1.2942181 | F10: 32.716788
A11: 2019-08 | B11: 아랍에미리트 연합 | C11: 427071 | D11: 0.15514259 | E11: 1.3865942 | F11: -46.690824
A12: 2019-09 | B12: 아랍에미리트 연합 | C12: 777152 | D12: 0.30504402 | E12: 1.2394769 | F12: 81.972553
A13: 2019-10 | B13: 아랍에미리트 연합 | C13: 1429074 | D13: 0.54148424 | E13: 1.2851385 | F13: 83.886035
A14: 2019-11 | B14: 아랍에미리트 연합 | C14: 707531 | D14: 0.30685963 | E14: 1.4558251 | F14: -50.490248
A15: 2019-12 | B15: 아랍에미리트 연합 | C15: 746526 | D15: 0.29814533 | E15: 1.0962203 | F15: 5.5114193
A16: 2020-01 | B16: 아랍에미리트 연합 | C16: 1195200 | D16: 0.55777151 | E16: 1.2581053 | F16: 60.101591 | G16: 344.67263
A17: 2020-02 | B17: 아랍에미리트 연합 | C17: 626681 | D17: 0.27553157 | E17: 1.215676 | F17: -47.566851 | G17: 86.829702
A18: 2020-03 | B18: 아랍에미리트 연합 | C18: 812247 | D18: 0.35350652 | E18: 1.4224991 | F18: 29.610918 | G18: 339.15213
A19: 2020-04 | B19: 아랍에미리트 연합 | C19: 2098814 | D19: 1.0291959 | E19: 1.0829794 | F19: 158.39603 | G19: 140.5967
A20: 2020-05 | B20: 아랍에미리트 연합 | C20: 473774 | D20: 0.21788665 | E20: 1.4144619 | F20: -77.426585 | G20: 47.779136
A21: 2020-06 | B21: 아랍에미리트 연합 | C21: 270499 | D21: 0.12247817 | E21: 1.3067585 | F21: -42.905478 | G21: -55.188095
A22: 2020-07 | B22: 아랍에미리트 연합 | C22: 705237 | D22: 0.31660148 | E22: 1.488784 | F22: 160.71705 | G22: -11.968729
A23: 2020-08 | B23: 아랍에미리트 연합 | C23: 533782 | D23: 0.25113249 | E23: 1.5516919 | F23: -24.311685 | G23: 24.986712
A24: 2020-09 | B24: 아랍에미리트 연합 | C24: 171129 | D24: 0.071815695 | E24: 1.0007544 | F24: -67.940283 | G24: -77.979983
A25: 2020-10 | B25: 아랍에미리트 연합 | C25: 177790 | D25: 0.082373467 | E25: 1.0397076 | F25: 3.8923853 | G25: -87.559077
A26: 2020-11 | B26: 아랍에미리트 연합 | C26: 80364 | D26: 0.039973605 | E26: 1.1480571 | F26: -54.798358 | G26: -88.641628
A27: 2020-12 | B27: 아랍에미리트 연합 | C27: 287706 | D27: 0.12216319 | E27: 1.3571038 | F27: 258.00358 | G27: -61.460686
... A37: 2021-10 | B37: 아랍에미리트 연합 | C37: 374317 | D37: 0.10226649 | E37: 1.6738603 | F37: -19.059419 | G37: 110.53884
A38: 2021-11 | B38: 아랍에미리트 연합 | C38: 0 | D38: 0 | F38: -100 | G38: -100
A39: 2021-12 | B39: 아랍에미리트 연합 | C39: 703116 | D39: 0.1869957 | E39: 1.5979909 | G39: 144.38698
A40: 2022-01 | B40: 아랍에미리트 연합 | C40: 394006 | D40: 0.091735809 | E40: 1.2709871 | F40: -43.962874 | G40: 68.110661
A41: 2022-02 | B41: 아랍에미리트 연합 | C41: 244843 | D41: 0.06175448 | E41: 1.1028964 | F41: -37.858053 | G41: -79.582073
A42: 2022-03 | B42: 아랍에미리트 연합 | C42: 616795 | D42: 0.16491201 | E42: 1.6490963 | F42: 151.91449 | G42: -34.931471
A43: 2022-04 | B43: 아랍에미리트 연합 | C43: 2264336 | D43: 0.72833095 | E43: 1.4528944 | F43: 267.11322 | G43: 235.36775
A44: 2022-05 | B44: 아랍에미리트 연합 | C44: 476707 | D44: 0.13387382 | E44: 1.4489222 | F44: -78.947162 | G44: -70.304679
A45: 2022-06 | B45: 아랍에미리트 연합 | C45: 413704 | D45: 0.14126694 | E45: 1.5181798 | F45: -13.216294 | G45: -72.532588
A46: 2022-07 | B46: 아랍에미리트 연합 | C46: 1719671 | D46: 0.59870287 | E46: 2.0669123 | F46: 315.67667 | G46: 181.77978
A47: 2022-08 | B47: 아랍에미리트 연합 | C47: 1449969 | D47: 0.57000152 | E47: 1.7385719 | F47: -15.683349 | G47: 263.38618
A48: 2022-09 | B48: 아랍에미리트 연합 | C48: 790065 | D48: 0.32473721 | E48: 2.493892 | F48: -45.511594 | G48: 70.84001
A49: 2022-10 | B49: 아랍에미리트 연합 | C49: 2313814 | D49: 1.0383951 | E49: 1.2248883 | F49: 192.86375 | G49: 518.14291
A50: 2022-11 | B50: 아랍에미리트 연합 | C50: 1370016 | D50: 0.67117701 | E50: 1.1949447 | F50: -40.789709
...

Sheet 조선_제품
A1: 조선 · 제품믹스 월별 (HD한국조선해양, 한화오션, 삼성중공업, HD현대미포)
A3: 월 | B3: 품목 | C3: 수출액(USD) | D3: 중량(kg) | E3: ASP(USD/kg) | F3: MoM(%) | G3: YoY(%)
A4: 2019-01 | B4: 기타선박(LNG·컨테이너) | C4: 461258250 | D4: 226513137 | E4: 2.0363422
A5: 2019-02 | B5: 기타선박(LNG·컨테이너) | C5: 43918553 | D5: 23764000 | E5: 1.8481128 | F5: -90.478533
A6: 2019-03 | B6: 기타선박(LNG·컨테이너) | C6: 417456484 | D6: 293157200 | E6: 1.4240022 | F6: 850.52422
A7: 2019-04 | B7: 기타선박(LNG·컨테이너) | C7: 338163533 | D7: 166290268 | E7: 2.0335738 | F7: -18.994303
A8: 2019-05 | B8: 기타선박(LNG·컨테이너) | C8: 260369800 | D8: 264458000 | E8: 0.98454121 | F8: -23.004767
A9: 2019-06 | B9: 기타선박(LNG·컨테이너) | C9: 452699828 | D9: 244153900 | E9: 1.8541577 | F9: 73.868025
A10: 2019-07 | B10: 기타선박(LNG·컨테이너) | C10: 750898971 | D10: 368394537 | E10: 2.038301 | F10: 65.871274
A11: 2019-08 | B11: 기타선박(LNG·컨테이너) | C11: 613624113 | D11: 259841600 | E11: 2.3615315 | F11: -18.281402
A12: 2019-09 | B12: 기타선박(LNG·컨테이너) | C12: 294727402 | D12: 194950800 | E12: 1.511804 | F12: -51.96939
A13: 2019-10 | B13: 기타선박(LNG·컨테이너) | C13: 454229819 | D13: 355515600 | E13: 1.2776649 | F13: 54.118625
A14: 2019-11 | B14: 기타선박(LNG·컨테이너) | C14: 397373268 | D14: 313798200 | E14: 1.2663338 | F14: -12.517133
A15: 2019-12 | B15: 기타선박(LNG·컨테이너) | C15: 236706984 | D15: 177884900 | E15: 1.330675 | F15: -40.432082
A16: 2020-01 | B16: 기타선박(LNG·컨테이너) | C16: 479414660 | D16: 227906000 | E16: 2.1035631 | F16: 102.53507 | G16: 3.9362786
A17: 2020-02 | B17: 기타선박(LNG·컨테이너) | C17: 366187837 | D17: 401690900 | E17: 0.91161596 | F17: -23.617722 | G17: 733.78848
A18: 2020-03 | B18: 기타선박(LNG·컨테이너) | C18: 503165932 | D18: 242156600 | E18: 2.0778535 | F18: 37.406511 | G18: 20.531349
A19: 2020-04 | B19: 기타선박(LNG·컨테이너) | C19: 469662791 | D19: 332406300 | E19: 1.4129178 | F19: -6.6584677 | G19: 38.886292
A20: 2020-05 | B20: 기타선박(LNG·컨테이너) | C20: 385587317 | D20: 244294800 | E20: 1.5783689 | F20: -17.901242 | G20: 48.092182
A21: 2020-06 | B21: 기타선박(LNG·컨테이너) | C21: 142217437 | D21: 568894000 | E21: 0.24998934 | F21: -63.116671 | G21: -68.584605
A22: 2020-07 | B22: 기타선박(LNG·컨테이너) | C22: 871514124 | D22: 651593082 | E22: 1.3375129 | F22: 512.80399 | G22: 16.062767
A23: 2020-08 | B23: 기타선박(LNG·컨테이너) | C23: 525189783 | D23: 142202000 | E23: 3.6932658 | F23: -39.738236 | G23: -14.411808
A24: 2020-09 | B24: 기타선박(LNG·컨테이너) | C24: 375852278 | D24: 498320340 | E24: 0.75423828 | F24: -28.43496 | G24: 27.525393
A25: 2020-10 | B25: 기타선박(LNG·컨테이너) | C25: 672796893 | D25: 432815600 | E25: 1.5544654 | F25: 79.005671 | G25: 48.118169
A26: 2020-11 | B26: 기타선박(LNG·컨테이너) | C26: 350529067 | D26: 332143700 | E26: 1.0553537 | F26: -47.89972 | G26: -11.788463
A27: 2020-12 | B27: 기타선박(LNG·컨테이너) | C27: 1129455039 | D27: 556369100 | E27: 2.0300463 | F27: 222.21437 | G27: 377.15324
... A92: 2026-05 | B92: 기타선박(LNG·컨테이너) | C92: 615633660 | D92: 96593003 | E92: 6.3734809 | F92: 85.072926 | G92: -57.494495
A93: 2026-06 | B93: 기타선박(LNG·컨테이너) | F93: 0 | G93: -51.983219
A94: 2019-01 | B94: 선박엔진 | C94: 31147712 | D94: 4394342 | E94: 7.0881402
A95: 2019-02 | B95: 선박엔진 | C95: 24507881 | D95: 2692400 | E95: 9.1026151 | F95: -21.317235
A96: 2019-03 | B96: 선박엔진 | C96: 27894463 | D96: 3805268 | E96: 7.3304858 | F96: 13.818339
A97: 2019-04 | B97: 선박엔진 | C97: 42202508 | D97: 5808064 | E97: 7.266192 | F97: 51.293495
A98: 2019-05 | B98: 선박엔진 | C98: 43601044 | D98: 6095630 | E98: 7.1528364 | F98: 3.3138694
A99: 2019-06 | B99: 선박엔진 | C99: 25150208 | D99: 3246469 | E99: 7.7469423 | F99: -42.317418
A100: 2019-07 | B100: 선박엔진 | C100: 45929152 | D100: 6742770 | E100: 6.8116148 | F100: 82.619372
A101: 2019-08 | B101: 선박엔진 | C101: 34948952 | D101: 4988489 | E101: 7.0059194 | F101: -23.906821
A102: 2019-09 | B102: 선박엔진 | C102: 36957929 | D102: 5765706 | E102: 6.4099573 | F102: 5.7483183
A103: 2019-10 | B103: 선박엔진 | C103: 77836537 | D103: 10977648 | E103: 7.0904566 | F103: 110.60849
A104: 2019-11 | B104: 선박엔진 | C104: 37345398 | D104: 6306092 | E104: 5.9221144 | F104: -52.020735
A105: 2019-12 | B105: 선박엔진 | C105: 60752171 | D105: 8978677 | E105: 6.766272 | F105: 62.676459
...

Sheet 조선_국가
A1: 조선 · 향지별 월별 (대표 HS 890190)
A3: 월 | B3: 향지 | C3: 수출액(USD) | D3: 비중(%) | E3: ASP(USD/kg) | F3: MoM(%) | G3: YoY(%)
A4: 2019-03 | B4: 아랍에미리트 연합 | C4: 22500000 | D4: 5.3897833 | E4: 0.24077047
A5: 2019-07 | B5: 아랍에미리트 연합 | C5: 9750000 | D5: 1.2984436 | E5: 0.33236748 | F5: -56.666667
A6: 2019-12 | B6: 아랍에미리트 연합 | C6: 304000 | D6: 0.12842883 | E6: 0.30552764 | F6: -96.882051
A7: 2020-01 | B7: 아랍에미리트 연합 | C7: 1515000 | D7: 0.31601036 | E7: 0.22368227 | F7: 398.35526
A8: 2021-03 | B8: 아랍에미리트 연합 | C8: 1090000 | D8: 0.11709964 | E8: 0.57459146 | F8: -28.052805
A9: 2021-05 | B9: 아랍에미리트 연합 | C9: 430000 | D9: 0.078148919 | E9: 0.27388535 | F9: -60.550459
A10: 2022-03 | B10: 아랍에미리트 연합 | C10: 1022235 | D10: 0.19996151 | E10: 0.25215466 | F10: 137.72907
A11: 2022-04 | B11: 아랍에미리트 연합 | C11: 950000 | D11: 1.5441882 | E11: 0.30254777 | F11: -7.0663791
A12: 2022-09 | B12: 아랍에미리트 연합 | C12: 5525000 | D12: 1.0967083 | E12: 0.4043176 | F12: 481.57895
A13: 2022-10 | B13: 아랍에미리트 연합 | C13: 2600000 | D13: 0.31374284 | E13: 1.6149068 | F13: -52.941176
A14: 2023-02 | B14: 아랍에미리트 연합 | C14: 1880000 | D14: 0.27684092 | E14: 0.70517629 | F14: -27.692308
A15: 2023-06 | B15: 아랍에미리트 연합 | C15: 301995 | D15: 0.023377609 | E15: 0.21963273 | F15: -83.936436
A16: 2023-12 | B16: 아랍에미리트 연합 | C16: 3700000 | D16: 0.48072411 | E16: 0.61625583 | F16: 1125.1858 | G16: -83.555556
A17: 2024-01 | B17: 아랍에미리트 연합 | C17: 823107 | D17: 0.052024365 | E17: 0.17568986 | F17: -77.753865 | G17: -91.557877
A18: 2024-04 | B18: 아랍에미리트 연합 | C18: 450000 | D18: 0.035717504 | E18: 0.28301887 | F18: -45.329101 | G18: 48.026316
A19: 2024-07 | B19: 아랍에미리트 연합 | C19: 3660000 | D19: 0.42711643 | E19: 1.0280899 | F19: 713.33333 | G19: 141.58416
A20: 2024-10 | B20: 아랍에미리트 연합 | C20: 1200000 | D20: 0.090310216 | E20: 0.43859649 | F20: -67.213115 | G20: 10.091743
A21: 2025-01 | B21: 아랍에미리트 연합 | C21: 400000 | D21: 0.031735685 | E21: 0.40120361 | F21: -66.666667 | G21: -6.9767442
A22: 2025-03 | B22: 아랍에미리트 연합 | C22: 0 | D22: 0 | F22: -100 | G22: -100
A23: 2025-05 | B23: 아랍에미리트 연합 | C23: 550000 | D23: 0.037973927 | E23: 0.34788109 | G23: -42.105263
A24: 2025-09 | B24: 아랍에미리트 연합 | C24: 647235 | D24: 0.076364136 | E24: 0.20032033 | F24: 17.679091 | G24: -88.285339
A25: 2026-01 | B25: 아랍에미리트 연합 | C25: 2054654 | D25: 0.50051505 | E25: 1.0242542 | F25: 217.451 | G25: -20.974846
A26: 2026-02 | B26: 아랍에미리트 연합 | C26: 140 | D26: 2.2533131e-05 | E26: 23.333333 | F26: -99.993186 | G26: -99.992553
A27: 2026-05 | B27: 아랍에미리트 연합 | C27: 700000 | D27: 0.11370398 | E27: 0.19668446 | F27: 499900 | G27: 131.79192
A28: 2019-04 | B28: 앙귈라 | C28: 630000 | D28: 0.1863004 | E28: 0.3372591
A29: 2020-07 | B29: 호주 | C29: 5273715 | D29: 0.605121 | E29: 0.10831875
A30: 2021-07 | B30: 호주 | C30: 0 | D30: 0 | F30: -100
A31: 2021-08 | B31: 호주 | C31: 0 | D31: 0
A32: 2022-01 | B32: 호주 | C32: 13295000 | D32: 12.98834 | E32: 0.23366786
A33: 2022-03 | B33: 호주 | C33: 27000000 | D33: 5.281526 | E33: 0.44662796 | F33: 103.08387
A34: 2022-04 | B34: 호주 | C34: 0 | D34: 0 | F34: -100
A35: 2022-05 | B35: 호주 | C35: 53260000 | D35: 5.4261061 | E35: 0.4405075
A36: 2022-10 | B36: 호주 | C36: 0 | D36: 0 | F36: -100
A37: 2023-01 | B37: 호주 | C37: 0 | D37: 0
A38: 2023-02 | B38: 호주 | C38: 23500000 | D38: 3.4605114 | E38: 0.3963101
A39: 2024-10 | B39: 호주 | C39: 21110000 | D39: 1.5887072 | E39: 0.35810008 | F39: -10.170213
A40: 2025-01 | B40: 호주 | C40: 0 | D40: 0 | F40: -100
A41: 2025-04 | B41: 호주 | C41: 132438000 | D41: 21.651233 | E41: 0.72787329 | G41: 2411.2847
...

Sheet 의료기기_제품
A1: 의료기기 · 제품믹스 월별 (오스템임플란트, 덴티움, 클래시스, 레이언스, 바텍)
A3: 월 | B3: 품목 | C3: 수출액(USD) | D3: 중량(kg) | E3: ASP(USD/kg) | F3: MoM(%) | G3: YoY(%)
A4: 2019-01 | B4: CT | C4: 1208539 | D4: 12125 | E4: 99.67332
A5: 2019-02 | B5: CT | C5: 1499008 | D5: 11813 | E5: 126.89478 | F5: 24.034723
A6: 2019-03 | B6: CT | C6: 1843093 | D6: 12549 | E6: 146.8717 | F6: 22.95418
A7: 2019-04 | B7: CT | C7: 1479800 | D7: 14931 | E7: 99.109236 | F7: -19.711051
A8: 2019-05 | B8: CT | C8: 1906878 | D8: 10492 | E8: 181.7459 | F8: 28.860522
A9: 2019-06 | B9: CT | C9: 2250221 | D9: 14959 | E9: 150.4259 | F9: 18.005504
A10: 2019-07 | B10: CT | C10: 1858742 | D10: 16392 | E10: 113.39324 | F10: -17.397358
A11: 2019-08 | B11: CT | C11: 1515837 | D11: 14333 | E11: 105.75853 | F11: -18.44823
A12: 2019-09 | B12: CT | C12: 2529097 | D12: 24574 | E12: 102.9176 | F12: 66.844918
A13: 2019-10 | B13: CT | C13: 1972094 | D13: 16047 | E13: 122.89487 | F13: -22.02379
A14: 2019-11 | B14: CT | C14: 2110618 | D14: 22701 | E14: 92.974671 | F14: 7.0242088
A15: 2019-12 | B15: CT | C15: 3017830 | D15: 28012 | E15: 107.73347 | F15: 42.98324
A16: 2020-01 | B16: CT | C16: 990412 | D16: 8926 | E16: 110.9581 | F16: -67.181319 | G16: -18.048818
A17: 2020-02 | B17: CT | C17: 776075 | D17: 10634 | E17: 72.980534 | F17: -21.641196 | G17: -48.227428
A18: 2020-03 | B18: CT | C18: 2469009 | D18: 26480 | E18: 93.240521 | F18: 218.14051 | G18: 33.960088
A19: 2020-04 | B19: CT | C19: 154634 | D19: 799 | E19: 193.53442 | F19: -93.737001 | G19: -89.550345
A20: 2020-05 | B20: CT | C20: 1991009 | D20: 29815 | E20: 66.778769 | F20: 1187.5622 | G20: 4.411976
A21: 2020-06 | B21: CT | C21: 5071942 | D21: 47258 | E21: 107.32452 | F21: 154.74229 | G21: 125.39751
A22: 2020-07 | B22: CT | C22: 2956027 | D22: 37978 | E22: 77.835247 | F22: -41.718044 | G22: 59.033744
A23: 2020-08 | B23: CT | C23: 3292157 | D23: 33791 | E23: 97.427037 | F23: 11.371006 | G23: 117.1841
A24: 2020-09 | B24: CT | C24: 1051915 | D24: 9091 | E24: 115.70949 | F24: -68.047848 | G24: -58.407487
A25: 2020-10 | B25: CT | C25: 1637131 | D25: 18203 | E25: 89.937428 | F25: 55.633392 | G25: -16.985144
A26: 2020-11 | B26: CT | C26: 3129829 | D26: 28929 | E26: 108.19002 | F26: 91.177676 | G26: 48.289695
A27: 2020-12 | B27: CT | C27: 3442103 | D27: 36968 | E27: 93.110339 | F27: 9.9773502 | G27: 14.058877
... A92: 2026-05 | B92: CT | C92: 3463360 | D92: 43086 | E92: 80.382491 | F92: 26.586322 | G92: 20.373798
A93: 2026-06 | B93: CT | F93: 0 | G93: -20.460057
A94: 2019-01 | B94: 기타 의료기기 | C94: 35540753 | D94: 656301 | E94: 54.153129
A95: 2019-02 | B95: 기타 의료기기 | C95: 32416501 | D95: 546007 | E95: 59.37012 | F95: -8.7906185
A96: 2019-03 | B96: 기타 의료기기 | C96: 55818348 | D96: 1060652 | E96: 52.626449 | F96: 72.191157
A97: 2019-04 | B97: 기타 의료기기 | C97: 44655703 | D97: 759575 | E97: 58.79038 | F97: -19.998164
A98: 2019-05 | B98: 기타 의료기기 | C98: 46161059 | D98: 738872 | E98: 62.475042 | F98: 3.3710274
A99: 2019-06 | B99: 기타 의료기기 | C99: 46136177 | D99: 755205 | E99: 61.090932 | F99: -0.053902576
A100: 2019-07 | B100: 기타 의료기기 | C100: 42126557 | D100: 646414 | E100: 65.169623 | F100: -8.6908371
A101: 2019-08 | B101: 기타 의료기기 | C101: 41717014 | D101: 632173 | E101: 65.98987 | F101: -0.97217297
A102: 2019-09 | B102: 기타 의료기기 | C102: 51725361 | D102: 963887 | E102: 53.663304 | F102: 23.991044
A103: 2019-10 | B103: 기타 의료기기 | C103: 60940480 | D103: 1148632 | E103: 53.054834 | F103: 17.815475
A104: 2019-11 | B104: 기타 의료기기 | C104: 57066580 | D104: 1110759 | E104: 51.376203 | F104: -6.3568584
A105: 2019-12 | B105: 기타 의료기기 | C105: 65086212 | D105: 1027716 | E105: 63.330932 | F105: 14.053115
...

Sheet 의료기기_국가
A1: 의료기기 · 향지별 월별 (대표 HS 901890)
A3: 월 | B3: 향지 | C3: 수출액(USD) | D3: 비중(%) | E3: ASP(USD/kg) | F3: MoM(%) | G3: YoY(%)
A4: 2020-05 | B4: 안도라 | C4: 0 | D4: 0
A5: 2022-05 | B5: 안도라 | C5: 4500 | D5: 0.0072713253 | E5: 236.84211
A6: 2019-01 | B6: 아랍에미리트 연합 | C6: 1014969 | D6: 2.8557892 | E6: 231.72808
A7: 2019-02 | B7: 아랍에미리트 연합 | C7: 401508 | D7: 1.2385914 | E7: 279.01876 | F7: -60.441353
A8: 2019-03 | B8: 아랍에미리트 연합 | C8: 1824761 | D8: 3.2691061 | E8: 245.29655 | F8: 354.47687
A9: 2019-04 | B9: 아랍에미리트 연합 | C9: 532105 | D9: 1.1915723 | E9: 193.91582 | F9: -70.839743
A10: 2019-05 | B10: 아랍에미리트 연합 | C10: 1560594 | D10: 3.3807587 | E10: 253.83767 | F10: 193.28685
A11: 2019-06 | B11: 아랍에미리트 연합 | C11: 804355 | D11: 1.7434366 | E11: 244.63352 | F11: -48.458408
A12: 2019-07 | B12: 아랍에미리트 연합 | C12: 1527456 | D12: 3.6258743 | E12: 206.3572 | F12: 89.898241
A13: 2019-08 | B13: 아랍에미리트 연합 | C13: 373584 | D13: 0.89551951 | E13: 239.47692 | F13: -75.542078
A14: 2019-09 | B14: 아랍에미리트 연합 | C14: 375256 | D14: 0.72547778 | E14: 279.20833 | F14: 0.44755664
A15: 2019-10 | B15: 아랍에미리트 연합 | C15: 756244 | D15: 1.2409551 | E15: 279.36609 | F15: 101.52749
A16: 2019-11 | B16: 아랍에미리트 연합 | C16: 881939 | D16: 1.5454562 | E16: 240.57256 | F16: 16.620958
A17: 2019-12 | B17: 아랍에미리트 연합 | C17: 2307823 | D17: 3.545794 | E17: 258.66655 | F17: 161.67603
A18: 2020-01 | B18: 아랍에미리트 연합 | C18: 351007 | D18: 0.90473815 | E18: 263.32108 | F18: -84.790558 | G18: -65.416973
A19: 2020-02 | B19: 아랍에미리트 연합 | C19: 1147416 | D19: 2.6109809 | E19: 191.236 | F19: 226.89263 | G19: 185.77662
A20: 2020-03 | B20: 아랍에미리트 연합 | C20: 1175455 | D20: 2.3877989 | E20: 233.04025 | F20: 2.4436647 | G20: -35.583071
A21: 2020-04 | B21: 아랍에미리트 연합 | C21: 165553 | D21: 0.62296822 | E21: 110.81191 | F21: -85.915837 | G21: -68.887156
A22: 2020-05 | B22: 아랍에미리트 연합 | C22: 124081 | D22: 0.55944545 | E22: 37.726057 | F22: -25.050588 | G22: -92.049117
A23: 2020-06 | B23: 아랍에미리트 연합 | C23: 178127 | D23: 0.51113202 | E23: 345.20736 | F23: 43.557031 | G23: -77.854679
A24: 2020-07 | B24: 아랍에미리트 연합 | C24: 329866 | D24: 0.84707694 | E24: 160.05143 | F24: 85.185851 | G24: -78.404222
A25: 2020-08 | B25: 아랍에미리트 연합 | C25: 802957 | D25: 2.1232364 | E25: 233.01132 | F25: 143.41915 | G25: 114.93346
A26: 2020-09 | B26: 아랍에미리트 연합 | C26: 563369 | D26: 1.081 | E26: 258.54475 | F26: -29.838211 | G26: 50.129245
A27: 2020-10 | B27: 아랍에미리트 연합 | C27: 1663631 | D27: 3.3832822 | E27: 239.85453 | F27: 195.30042 | G27: 119.98601
A28: 2020-11 | B28: 아랍에미리트 연합 | C28: 1271541 | D28: 2.5037684 | E28: 228.16095 | F28: -23.568327 | G28: 44.175618
A29: 2020-12 | B29: 아랍에미리트 연합 | C29: 1560074 | D29: 2.7653756 | E29: 240.67788 | F29: 22.6916 | G29: -32.400622
... A94: 2026-05 | B94: 아랍에미리트 연합 | C94: 813800 | D94: 0.85274897 | E94: 281.5917 | F94: 32.228236 | G94: -24.962541
A95: 2019-05 | B95: 아프카니스탄 | C95: 61100 | D95: 0.13236265 | E95: 174.57143
A96: 2020-03 | B96: 아프카니스탄 | C96: 21200 | D96: 0.043065313 | E96: 157.03704 | F96: -65.302782
A97: 2021-01 | B97: 아프카니스탄 | C97: 13270 | D97: 0.029721075 | E97: 66.35 | F97: -37.40566
A98: 2023-03 | B98: 아프카니스탄 | C98: 550 | D98: 0.000654511 | E98: 5.5 | F98: -95.855313
A99: 2024-08 | B99: 아프카니스탄 | C99: 11750 | D99: 0.013369174 | E99: 146.875 | F99: 2036.3636
A100: 2023-06 | B100: 안티가 바부다 | C100: 180 | D100: 0.00021181976 | E100: 180
A101: 2023-07 | B101: 안티가 바부다 | C101: 2900 | D101: 0.0039427146 | E101: 223.07692 | F101: 1511.1111
A102: 2023-10 | B102: 안티가 바부다 | C102: 1800 | D102: 0.002497932 | E102: 900 | F102: -37.931034
A103: 2024-11 | B103: 안티가 바부다 | C103: 3800 | D103: 0.0039680536 | E103: 271.42857 | F103: 111.11111
A104: 2019-04 | B104: 앙귈라 | C104: 28800 | D104: 0.064493442 | E104: 221.53846
A105: 2019-07 | B105: 앙귈라 | C105: 2000 | D105: 0.004747599 | E105: 1000 | F105: -93.055556
...

Sheet K푸드_제품
A1: K푸드 · 제품믹스 월별 (삼양식품, 농심, 오뚜기, CJ제일제당, 하이트진로)
A3: 월 | B3: 품목 | C3: 수출액(USD) | D3: 중량(kg) | E3: ASP(USD/kg) | F3: MoM(%) | G3: YoY(%)
A4: 2019-01 | B4: 김치·조제채소 | C4: 9656217 | D4: 2688149 | E4: 3.5921435
A5: 2019-02 | B5: 김치·조제채소 | C5: 8080013 | D5: 2296511 | E5: 3.5183864 | F5: -16.323204
A6: 2019-03 | B6: 김치·조제채소 | C6: 9588529 | D6: 2674599 | E6: 3.5850342 | F6: 18.669722
A7: 2019-04 | B7: 김치·조제채소 | C7: 9834272 | D7: 2779477 | E7: 3.5381735 | F7: 2.5628853
A8: 2019-05 | B8: 김치·조제채소 | C8: 9612362 | D8: 2644689 | E8: 3.6345907 | F8: -2.2564965
A9: 2019-06 | B9: 김치·조제채소 | C9: 8896822 | D9: 2470148 | E9: 3.6017364 | F9: -7.443956
A10: 2019-07 | B10: 김치·조제채소 | C10: 9628999 | D10: 2698582 | E10: 3.5681699 | F10: 8.2296465
A11: 2019-08 | B11: 김치·조제채소 | C11: 9695976 | D11: 2676980 | E11: 3.621983 | F11: 0.69557594
A12: 2019-09 | B12: 김치·조제채소 | C12: 9109188 | D12: 2520134 | E12: 3.6145649 | F12: -6.0518714
A13: 2019-10 | B13: 김치·조제채소 | C13: 9708383 | D13: 2678237 | E13: 3.6249156 | F13: 6.5779189
A14: 2019-11 | B14: 김치·조제채소 | C14: 10021489 | D14: 2712837 | E14: 3.6940992 | F14: 3.2251097
A15: 2019-12 | B15: 김치·조제채소 | C15: 9195503 | D15: 2572138 | E15: 3.5750426 | F15: -8.2421484
A16: 2020-01 | B16: 김치·조제채소 | C16: 9411289 | D16: 2653162 | E16: 3.5471973 | F16: 2.3466471 | G16: -2.5364799
A17: 2020-02 | B17: 김치·조제채소 | C17: 10371146 | D17: 2935673 | E17: 3.5328001 | F17: 10.198996 | G17: 28.355561
A18: 2020-03 | B18: 김치·조제채소 | C18: 12299771 | D18: 3448102 | E18: 3.5671134 | F18: 18.596065 | G18: 28.275891
A19: 2020-04 | B19: 김치·조제채소 | C19: 15865089 | D19: 4421036 | E19: 3.5885455 | F19: 28.986865 | G19: 61.324488
A20: 2020-05 | B20: 김치·조제채소 | C20: 14978595 | D20: 4072675 | E20: 3.6778272 | F20: -5.5877027 | G20: 55.826372
A21: 2020-06 | B21: 김치·조제채소 | C21: 13942297 | D21: 3916198 | E21: 3.5601614 | F21: -6.9185261 | G21: 56.710981
A22: 2020-07 | B22: 김치·조제채소 | C22: 13571121 | D22: 3685408 | E22: 3.6823931 | F22: -2.6622299 | G22: 40.940102
A23: 2020-08 | B23: 김치·조제채소 | C23: 14039209 | D23: 3788813 | E23: 3.7054373 | F23: 3.4491476 | G23: 44.794181
A24: 2020-09 | B24: 김치·조제채소 | C24: 11601800 | D24: 3026928 | E24: 3.8328629 | F24: -17.361441 | G24: 27.363712
A25: 2020-10 | B25: 김치·조제채소 | C25: 11687929 | D25: 3045800 | E25: 3.8373921 | F25: 0.74237618 | G25: 20.390069
A26: 2020-11 | B26: 김치·조제채소 | C26: 13450544 | D26: 3612904 | E26: 3.7229176 | F26: 15.080644 | G26: 34.217021
A27: 2020-12 | B27: 김치·조제채소 | C27: 14236211 | D27: 3823581 | E27: 3.7232665 | F27: 5.8411541 | G27: 54.817099
... A92: 2026-05 | B92: 김치·조제채소 | C92: 14192108 | D92: 4209897 | E92: 3.3711295 | F92: -20.217574 | G92: 4.0068571
A93: 2026-06 | B93: 김치·조제채소 | F93: 0 | G93: -0.07268474
A94: 2019-01 | B94: 라면 | C94: 38874104 | D94: 12159278 | E94: 3.1970734
A95: 2019-02 | B95: 라면 | C95: 33387859 | D95: 10178908 | E95: 3.2801022 | F95: -14.112853
A96: 2019-03 | B96: 라면 | C96: 44549652 | D96: 13873596 | E96: 3.2111107 | F96: 33.430694
A97: 2019-04 | B97: 라면 | C97: 46026010 | D97: 14320936 | E97: 3.2138968 | F97: 3.3139608
A98: 2019-05 | B98: 라면 | C98: 45438594 | D98: 14159481 | E98: 3.2090579 | F98: -1.2762697
A99: 2019-06 | B99: 라면 | C99: 40652966 | D99: 12346265 | E99: 3.292734 | F99: -10.532078
A100: 2019-07 | B100: 라면 | C100: 43063770 | D100: 13450108 | E100: 3.2017416 | F100: 5.9302045
A101: 2019-08 | B101: 라면 | C101: 44267274 | D101: 13741491 | E101: 3.2214316 | F101: 2.7947019
A102: 2019-09 | B102: 라면 | C102: 42856639 | D102: 13370936 | E102: 3.2052086 | F102: -3.1866317
A103: 2019-10 | B103: 라면 | C103: 53264207 | D103: 16800029 | E103: 3.170483 | F103: 24.284611
A104: 2019-11 | B104: 라면 | C104: 51615259 | D104: 16355396 | E104: 3.155855 | F104: -3.09579
A105: 2019-12 | B105: 라면 | C105: 44537116 | D105: 14133873 | E105: 3.1510907 | F105: -13.713276
...

Sheet K푸드_국가
A1: K푸드 · 향지별 월별 (대표 HS 190230)
A3: 월 | B3: 향지 | C3: 수출액(USD) | D3: 비중(%) | E3: ASP(USD/kg) | F3: MoM(%) | G3: YoY(%)
A4: 2019-01 | B4: 아랍에미리트 연합 | C4: 344062 | D4: 0.88506734 | E4: 4.1377477
A5: 2019-02 | B5: 아랍에미리트 연합 | C5: 305580 | D5: 0.91524287 | E5: 4.9797927 | F5: -11.184612
A6: 2019-03 | B6: 아랍에미리트 연합 | C6: 434272 | D6: 0.97480447 | E6: 3.9162413 | F6: 42.114013
A7: 2019-04 | B7: 아랍에미리트 연합 | C7: 375485 | D7: 0.81581045 | E7: 4.1110746 | F7: -13.536908
A8: 2019-05 | B8: 아랍에미리트 연합 | C8: 339410 | D8: 0.74696413 | E8: 4.5974318 | F8: -9.6075742
A9: 2019-06 | B9: 아랍에미리트 연합 | C9: 221745 | D9: 0.54545836 | E9: 3.7008078 | F9: -34.667511
A10: 2019-07 | B10: 아랍에미리트 연합 | C10: 216360 | D10: 0.50241769 | E10: 4.6035022 | F10: -2.4284651
A11: 2019-08 | B11: 아랍에미리트 연합 | C11: 208166 | D11: 0.47024807 | E11: 3.5012951 | F11: -3.7872065
A12: 2019-09 | B12: 아랍에미리트 연합 | C12: 310739 | D12: 0.72506619 | E12: 4.1113375 | F12: 49.274617
A13: 2019-10 | B13: 아랍에미리트 연합 | C13: 466517 | D13: 0.87585459 | E13: 3.678924 | F13: 50.131461
A14: 2019-11 | B14: 아랍에미리트 연합 | C14: 475056 | D14: 0.92037899 | E14: 4.0099266 | F14: 1.8303727
A15: 2019-12 | B15: 아랍에미리트 연합 | C15: 406094 | D15: 0.91181028 | E15: 3.7989635 | F15: -14.516604
A16: 2020-01 | B16: 아랍에미리트 연합 | C16: 527858 | D16: 1.2560639 | E16: 4.396948 | F16: 29.984191 | G16: 53.419442
A17: 2020-02 | B17: 아랍에미리트 연합 | C17: 620434 | D17: 1.266316 | E17: 4.0386528 | F17: 17.53805 | G17: 103.03488
A18: 2020-03 | B18: 아랍에미리트 연합 | C18: 445376 | D18: 0.75392934 | E18: 4.4392437 | F18: -28.215411 | G18: 2.5569229
A19: 2020-04 | B19: 아랍에미리트 연합 | C19: 649576 | D19: 0.93627553 | E19: 3.7680171 | G19: 72.996524
A20: 2020-05 | B20: 아랍에미리트 연합 | C20: 350631 | D20: 0.56421351 | E20: 4.7314792 | F20: -46.021559 | G20: 3.3060311
A21: 2020-06 | B21: 아랍에미리트 연합 | C21: 314837 | D21: 0.51578473 | E21: 5.150539 | F21: -10.208453 | G21: 41.981555
A22: 2020-07 | B22: 아랍에미리트 연합 | C22: 125973 | D22: 0.19417077 | E22: 4.8404611 | F22: -59.987867 | G22: -41.776206
A23: 2020-08 | B23: 아랍에미리트 연합 | C23: 324644 | D23: 0.61197527 | E23: 3.5639525 | F23: 157.70919 | G23: 55.954383
A24: 2020-09 | B24: 아랍에미리트 연합 | C24: 232108 | D24: 0.39947692 | E24: 4.2912237 | F24: -28.503838 | G24: -25.304516
A25: 2020-10 | B25: 아랍에미리트 연합 | C25: 661364 | D25: 1.2288444 | E25: 4.2202512 | F25: 184.93805 | G25: 41.766324
A26: 2020-11 | B26: 아랍에미리트 연합 | C26: 377262 | D26: 0.71646532 | E26: 4.3111223 | F26: -42.95698 | G26: -20.585784
A27: 2020-12 | B27: 아랍에미리트 연합 | C27: 613644 | D27: 1.0072622 | E27: 3.9640317 | F27: 62.657251 | G27: 51.108857
A28: 2021-01 | B28: 아랍에미리트 연합 | C28: 613082 | D28: 1.0717173 | E28: 3.708748 | F28: -0.091584045 | G28: 16.145251
A29: 2021-02 | B29: 아랍에미리트 연합 | C29: 1037525 | D29: 1.9779656 | E29: 3.8945403 | F29: 69.231033 | G29: 67.225684
A30: 2021-03 | B30: 아랍에미리트 연합 | C30: 779933 | D30: 1.1100031 | E30: 4.0206462 | F30: -24.827546 | G30: 75.117878
A31: 2021-04 | B31: 아랍에미리트 연합 | C31: 635933 | D31: 0.94958918 | E31: 3.7375724 | F31: -18.463124 | G31: -2.1002931
... A92: 2026-05 | B92: 아랍에미리트 연합 | C92: 1720444 | D92: 1.0511768 | E92: 4.3545512 | F92: 2706.0478 | G92: 10.965961
A93: 2019-11 | B93: 아프카니스탄 | C93: 9 | D93: 1.7436704e-05 | E93: 2.25
A94: 2021-12 | B94: 아프카니스탄 | C94: 17090 | D94: 0.023178905 | E94: 3.9197248 | F94: 189788.89
A95: 2022-11 | B95: 아프카니스탄 | C95: 41045 | D95: 0.056385891 | E95: 3.7060948 | F95: 140.16969
A96: 2023-06 | B96: 아프카니스탄 | C96: 51100 | D96: 0.051992713 | E96: 4.474606 | F96: 24.497503
A97: 2023-11 | B97: 아프카니스탄 | C97: 14927 | D97: 0.015102704 | E97: 3.9281579 | F97: -70.78865
A98: 2024-07 | B98: 아프카니스탄 | C98: 49941 | D98: 0.042326294 | E98: 4.4399893 | F98: 234.56823
A99: 2025-10 | B99: 아프카니스탄 | C99: 47244 | D99: 0.034398823 | E99: 4.2032028 | F99: -5.4003724
A100: 2025-12 | B100: 아프카니스탄 | C100: 96331 | D100: 0.063965689 | E100: 4.3178395 | F100: 103.90102
A101: 2026-01 | B101: 아프카니스탄 | C101: 237069 | D101: 0.17029131 | E101: 4.2173341 | F101: 146.09835
...
